[2024-05-15T13:09:28.556+0000] {task_context_logger.py:104} WARNING - Marking task instance <TaskInstance: json2csv_b.boygroup_extract scheduled__2024-05-15T08:22:00+00:00 [queued]> stuck in queued as failed. If the task instance has available retries, it will be retried.
[2024-05-15T13:09:28.928+0000] {task_context_logger.py:104} ERROR - Executor reports task instance <TaskInstance: json2csv_b.boygroup_extract scheduled__2024-05-15T08:22:00+00:00 [queued]> finished (failed) although the task says it's queued. (Info: None) Was the task killed externally?
