[2024-05-14T02:12:24.466+0000] {task_context_logger.py:104} WARNING - Marking task instance <TaskInstance: demo.hello scheduled__2022-09-09T00:00:00+00:00 [queued]> stuck in queued as failed. If the task instance has available retries, it will be retried.
[2024-05-14T02:12:25.560+0000] {task_context_logger.py:104} ERROR - Executor reports task instance <TaskInstance: demo.hello scheduled__2022-09-09T00:00:00+00:00 [queued]> finished (failed) although the task says it's queued. (Info: None) Was the task killed externally?
